2019-07-05 18:44:51 logger.py[line:96] DEBUG =================扫描程序开始==========================
2019-07-05 18:45:31 logger.py[line:96] DEBUG =================扫描程序开始==========================
2019-07-05 18:45:44 logger.py[line:90] ERROR HTTPConnectionPool(host='chrome-scan', port=4444): Max retries exceeded with url: /wd/hub/session (Caused by NewConnectionError('<urllib3.connection.HTTPConnection object at 0x000002224CDD48D0>: Failed to establish a new connection: [Errno 11001] getaddrinfo failed'))
2019-07-05 18:45:48 logger.py[line:90] ERROR 请检查好Chrome环境！
2019-07-05 18:50:35 logger.py[line:96] DEBUG =================扫描程序开始==========================
2019-07-05 18:50:46 logger.py[line:90] ERROR HTTPConnectionPool(host='chrome-scan', port=4444): Max retries exceeded with url: /wd/hub/session (Caused by NewConnectionError('<urllib3.connection.HTTPConnection object at 0x000001E5E7371D68>: Failed to establish a new connection: [Errno 11001] getaddrinfo failed'))
2019-07-05 18:50:51 logger.py[line:90] ERROR 请检查好Chrome环境！
2019-07-05 18:51:08 logger.py[line:96] DEBUG =================扫描程序开始==========================
2019-07-05 18:51:21 logger.py[line:90] ERROR HTTPConnectionPool(host='chrome-scan', port=4444): Max retries exceeded with url: /wd/hub/session (Caused by NewConnectionError('<urllib3.connection.HTTPConnection object at 0x0000020E11644940>: Failed to establish a new connection: [Errno 11001] getaddrinfo failed'))
2019-07-05 18:51:25 logger.py[line:90] ERROR 请检查好Chrome环境！
2019-07-05 18:51:52 logger.py[line:96] DEBUG =================扫描程序开始==========================
2019-07-05 18:52:05 logger.py[line:90] ERROR HTTPConnectionPool(host='chrome-scan', port=4444): Max retries exceeded with url: /wd/hub/session (Caused by NewConnectionError('<urllib3.connection.HTTPConnection object at 0x000001C64DEA8828>: Failed to establish a new connection: [Errno 11001] getaddrinfo failed'))
2019-07-05 18:52:09 logger.py[line:90] ERROR 请检查好Chrome环境！
2019-07-05 18:52:47 logger.py[line:96] DEBUG =================扫描程序开始==========================
2019-07-05 18:53:00 logger.py[line:90] ERROR HTTPConnectionPool(host='chrome-scan', port=4444): Max retries exceeded with url: /wd/hub/session (Caused by NewConnectionError('<urllib3.connection.HTTPConnection object at 0x000001CFE1A577B8>: Failed to establish a new connection: [Errno 11001] getaddrinfo failed'))
2019-07-05 18:53:04 logger.py[line:90] ERROR 请检查好Chrome环境！
2019-07-05 19:00:38 logger.py[line:96] DEBUG =================扫描程序开始==========================
2019-07-05 19:00:50 logger.py[line:90] ERROR HTTPConnectionPool(host='chrome-scan', port=4444): Max retries exceeded with url: /wd/hub/session (Caused by NewConnectionError('<urllib3.connection.HTTPConnection object at 0x00000179845B1CC0>: Failed to establish a new connection: [Errno 11001] getaddrinfo failed'))
2019-07-05 19:00:54 logger.py[line:90] ERROR 请检查好Chrome环境！
2019-07-05 19:01:23 logger.py[line:96] DEBUG =================扫描程序开始==========================
2019-07-05 19:01:36 logger.py[line:90] ERROR HTTPConnectionPool(host='chrome-scan', port=4444): Max retries exceeded with url: /wd/hub/session (Caused by NewConnectionError('<urllib3.connection.HTTPConnection object at 0x000001E84B464860>: Failed to establish a new connection: [Errno 11001] getaddrinfo failed'))
2019-07-05 19:01:40 logger.py[line:90] ERROR 请检查好Chrome环境！
2019-07-05 19:02:05 logger.py[line:96] DEBUG =================扫描程序开始==========================
2019-07-05 19:02:17 logger.py[line:90] ERROR HTTPConnectionPool(host='chrome-scan', port=4444): Max retries exceeded with url: /wd/hub/session (Caused by NewConnectionError('<urllib3.connection.HTTPConnection object at 0x0000024AA7972CF8>: Failed to establish a new connection: [Errno 11001] getaddrinfo failed'))
2019-07-05 19:02:21 logger.py[line:90] ERROR 请检查好Chrome环境！
2019-07-05 19:04:53 logger.py[line:96] DEBUG =================扫描程序开始==========================
2019-07-05 19:05:06 logger.py[line:90] ERROR HTTPConnectionPool(host='chrome-scan', port=4444): Max retries exceeded with url: /wd/hub/session (Caused by NewConnectionError('<urllib3.connection.HTTPConnection object at 0x000001755EE58550>: Failed to establish a new connection: [Errno 11001] getaddrinfo failed'))
2019-07-05 19:05:10 logger.py[line:90] ERROR 请检查好Chrome环境！
2019-07-05 19:06:50 logger.py[line:96] DEBUG =================扫描程序开始==========================
2019-07-05 19:07:02 logger.py[line:90] ERROR HTTPConnectionPool(host='chrome-scan', port=4444): Max retries exceeded with url: /wd/hub/session (Caused by NewConnectionError('<urllib3.connection.HTTPConnection object at 0x000002402E371D30>: Failed to establish a new connection: [Errno 11001] getaddrinfo failed'))
2019-07-05 19:07:07 logger.py[line:90] ERROR 请检查好Chrome环境！
