2019-07-08 09:10:02 logger.py[line:96] DEBUG =================扫描程序开始==========================
2019-07-08 09:10:41 logger.py[line:90] ERROR HTTPConnectionPool(host='chrome-scan', port=4444): Max retries exceeded with url: /wd/hub/session (Caused by NewConnectionError('<urllib3.connection.HTTPConnection object at 0x00000231FCA970F0>: Failed to establish a new connection: [Errno 11001] getaddrinfo failed'))
2019-07-08 09:10:43 logger.py[line:90] ERROR HTTPConnectionPool(host='chrome-scan', port=4444): Max retries exceeded with url: /wd/hub/session (Caused by NewConnectionError('<urllib3.connection.HTTPConnection object at 0x00000231FCA97198>: Failed to establish a new connection: [Errno 11001] getaddrinfo failed'))
2019-07-08 09:10:45 logger.py[line:90] ERROR HTTPConnectionPool(host='chrome-scan', port=4444): Max retries exceeded with url: /wd/hub/session (Caused by NewConnectionError('<urllib3.connection.HTTPConnection object at 0x00000231FCA972B0>: Failed to establish a new connection: [Errno 11001] getaddrinfo failed'))
2019-07-08 09:10:48 logger.py[line:90] ERROR HTTPConnectionPool(host='chrome-scan', port=4444): Max retries exceeded with url: /wd/hub/session (Caused by NewConnectionError('<urllib3.connection.HTTPConnection object at 0x00000231FCA973C8>: Failed to establish a new connection: [Errno 11001] getaddrinfo failed'))
2019-07-08 09:10:52 logger.py[line:90] ERROR 请检查好Chrome环境！
2019-07-08 09:10:52 logger.py[line:90] ERROR 请检查好Chrome环境！
2019-07-08 09:10:52 logger.py[line:90] ERROR 请检查好Chrome环境！
2019-07-08 09:10:53 logger.py[line:90] ERROR 请检查好Chrome环境！
2019-07-08 09:13:55 logger.py[line:96] DEBUG =================扫描程序结束==========================
2019-07-08 09:18:04 logger.py[line:96] DEBUG =================扫描程序开始==========================
2019-07-08 09:18:42 logger.py[line:90] ERROR HTTPConnectionPool(host='chrome-scan', port=4444): Max retries exceeded with url: /wd/hub/session (Caused by NewConnectionError('<urllib3.connection.HTTPConnection object at 0x000001F6B8E04E48>: Failed to establish a new connection: [Errno 11001] getaddrinfo failed'))
2019-07-08 09:18:45 logger.py[line:90] ERROR HTTPConnectionPool(host='chrome-scan', port=4444): Max retries exceeded with url: /wd/hub/session (Caused by NewConnectionError('<urllib3.connection.HTTPConnection object at 0x000001F6B8E04F60>: Failed to establish a new connection: [Errno 11001] getaddrinfo failed'))
2019-07-08 09:18:47 logger.py[line:90] ERROR HTTPConnectionPool(host='chrome-scan', port=4444): Max retries exceeded with url: /wd/hub/session (Caused by NewConnectionError('<urllib3.connection.HTTPConnection object at 0x000001F6B8E5B0B8>: Failed to establish a new connection: [Errno 11001] getaddrinfo failed'))
2019-07-08 09:18:49 logger.py[line:90] ERROR HTTPConnectionPool(host='chrome-scan', port=4444): Max retries exceeded with url: /wd/hub/session (Caused by NewConnectionError('<urllib3.connection.HTTPConnection object at 0x000001F6B8E5B1D0>: Failed to establish a new connection: [Errno 11001] getaddrinfo failed'))
2019-07-08 09:18:54 logger.py[line:90] ERROR 请检查好Chrome环境！
2019-07-08 09:18:54 logger.py[line:90] ERROR 请检查好Chrome环境！
2019-07-08 09:18:54 logger.py[line:90] ERROR 请检查好Chrome环境！
2019-07-08 09:18:54 logger.py[line:90] ERROR 请检查好Chrome环境！
2019-07-08 09:21:18 logger.py[line:96] DEBUG =================扫描程序结束==========================
2019-07-08 11:37:09 logger.py[line:96] DEBUG =================扫描程序开始==========================
2019-07-08 11:42:59 logger.py[line:96] DEBUG =================扫描程序开始==========================
2019-07-08 11:42:59 logger.py[line:96] DEBUG =================扫描程序结束==========================
2019-07-08 11:43:52 logger.py[line:96] DEBUG =================扫描程序开始==========================
2019-07-08 11:44:21 logger.py[line:96] DEBUG =================扫描程序开始==========================
2019-07-08 11:45:01 logger.py[line:96] DEBUG =================扫描程序开始==========================
2019-07-08 11:45:39 logger.py[line:90] ERROR HTTPConnectionPool(host='chrome-scan', port=4444): Max retries exceeded with url: /wd/hub/session (Caused by NewConnectionError('<urllib3.connection.HTTPConnection object at 0x000002BEBF6B7CC0>: Failed to establish a new connection: [Errno 11001] getaddrinfo failed'))
2019-07-08 11:45:42 logger.py[line:90] ERROR HTTPConnectionPool(host='chrome-scan', port=4444): Max retries exceeded with url: /wd/hub/session (Caused by NewConnectionError('<urllib3.connection.HTTPConnection object at 0x000002BEBF6B7DD8>: Failed to establish a new connection: [Errno 11001] getaddrinfo failed'))
2019-07-08 11:45:44 logger.py[line:90] ERROR HTTPConnectionPool(host='chrome-scan', port=4444): Max retries exceeded with url: /wd/hub/session (Caused by NewConnectionError('<urllib3.connection.HTTPConnection object at 0x000002BEBF6B7EF0>: Failed to establish a new connection: [Errno 11001] getaddrinfo failed'))
2019-07-08 11:45:46 logger.py[line:90] ERROR HTTPConnectionPool(host='chrome-scan', port=4444): Max retries exceeded with url: /wd/hub/session (Caused by NewConnectionError('<urllib3.connection.HTTPConnection object at 0x000002BEBF7170B8>: Failed to establish a new connection: [Errno 11001] getaddrinfo failed'))
2019-07-08 11:45:51 logger.py[line:90] ERROR 请检查好Chrome环境！
2019-07-08 11:45:51 logger.py[line:90] ERROR 请检查好Chrome环境！
2019-07-08 11:45:51 logger.py[line:90] ERROR 请检查好Chrome环境！
2019-07-08 11:45:51 logger.py[line:90] ERROR 请检查好Chrome环境！
2019-07-08 11:46:02 logger.py[line:96] DEBUG =================扫描程序结束==========================
2019-07-08 11:48:26 logger.py[line:96] DEBUG =================扫描程序开始==========================
2019-07-08 11:49:05 logger.py[line:90] ERROR HTTPConnectionPool(host='chrome-scan', port=4444): Max retries exceeded with url: /wd/hub/session (Caused by NewConnectionError('<urllib3.connection.HTTPConnection object at 0x000001BD5C98DF60>: Failed to establish a new connection: [Errno 11001] getaddrinfo failed'))
2019-07-08 11:49:07 logger.py[line:90] ERROR HTTPConnectionPool(host='chrome-scan', port=4444): Max retries exceeded with url: /wd/hub/session (Caused by NewConnectionError('<urllib3.connection.HTTPConnection object at 0x000001BD5C98D9E8>: Failed to establish a new connection: [Errno 11001] getaddrinfo failed'))
2019-07-08 11:49:09 logger.py[line:90] ERROR HTTPConnectionPool(host='chrome-scan', port=4444): Max retries exceeded with url: /wd/hub/session (Caused by NewConnectionError('<urllib3.connection.HTTPConnection object at 0x000001BD5C98D908>: Failed to establish a new connection: [Errno 11001] getaddrinfo failed'))
2019-07-08 11:49:11 logger.py[line:90] ERROR HTTPConnectionPool(host='chrome-scan', port=4444): Max retries exceeded with url: /wd/hub/session (Caused by NewConnectionError('<urllib3.connection.HTTPConnection object at 0x000001BD5C98DA58>: Failed to establish a new connection: [Errno 11001] getaddrinfo failed'))
2019-07-08 11:49:16 logger.py[line:90] ERROR 请检查好Chrome环境！
2019-07-08 11:49:16 logger.py[line:90] ERROR 请检查好Chrome环境！
2019-07-08 11:49:16 logger.py[line:90] ERROR 请检查好Chrome环境！
2019-07-08 11:49:16 logger.py[line:90] ERROR 请检查好Chrome环境！
2019-07-08 11:50:04 logger.py[line:96] DEBUG =================扫描程序结束==========================
2019-07-08 16:22:11 logger.py[line:96] DEBUG =================扫描程序开始==========================
2019-07-08 16:22:55 logger.py[line:90] ERROR HTTPConnectionPool(host='chrome-scan', port=4444): Max retries exceeded with url: /wd/hub/session (Caused by NewConnectionError('<urllib3.connection.HTTPConnection object at 0x0000029F2257E5F8>: Failed to establish a new connection: [Errno 11001] getaddrinfo failed'))
2019-07-08 16:22:58 logger.py[line:90] ERROR HTTPConnectionPool(host='chrome-scan', port=4444): Max retries exceeded with url: /wd/hub/session (Caused by NewConnectionError('<urllib3.connection.HTTPConnection object at 0x0000029F226050F0>: Failed to establish a new connection: [Errno 11001] getaddrinfo failed'))
2019-07-08 16:23:00 logger.py[line:90] ERROR HTTPConnectionPool(host='chrome-scan', port=4444): Max retries exceeded with url: /wd/hub/session (Caused by NewConnectionError('<urllib3.connection.HTTPConnection object at 0x0000029F22605390>: Failed to establish a new connection: [Errno 11001] getaddrinfo failed'))
2019-07-08 16:23:11 logger.py[line:90] ERROR HTTPConnectionPool(host='chrome-scan', port=4444): Max retries exceeded with url: /wd/hub/session (Caused by NewConnectionError('<urllib3.connection.HTTPConnection object at 0x0000029F225C9A90>: Failed to establish a new connection: [Errno 11001] getaddrinfo failed'))
2019-07-08 16:23:13 logger.py[line:90] ERROR 请检查好Chrome环境！
2019-07-08 16:23:13 logger.py[line:90] ERROR 请检查好Chrome环境！
2019-07-08 16:23:13 logger.py[line:90] ERROR 请检查好Chrome环境！
2019-07-08 16:23:16 logger.py[line:90] ERROR 请检查好Chrome环境！
2019-07-08 16:23:18 logger.py[line:96] DEBUG =================扫描程序结束==========================
2019-07-08 16:24:23 logger.py[line:96] DEBUG =================扫描程序开始==========================
2019-07-08 16:24:52 logger.py[line:96] DEBUG =================扫描程序开始==========================
2019-07-08 16:25:38 logger.py[line:90] ERROR HTTPConnectionPool(host='chrome-scan', port=4444): Max retries exceeded with url: /wd/hub/session (Caused by NewConnectionError('<urllib3.connection.HTTPConnection object at 0x000001DCAFD42E48>: Failed to establish a new connection: [Errno 11001] getaddrinfo failed'))
2019-07-08 16:25:40 logger.py[line:90] ERROR HTTPConnectionPool(host='chrome-scan', port=4444): Max retries exceeded with url: /wd/hub/session (Caused by NewConnectionError('<urllib3.connection.HTTPConnection object at 0x000001DCAFD42F60>: Failed to establish a new connection: [Errno 11001] getaddrinfo failed'))
2019-07-08 16:25:42 logger.py[line:90] ERROR HTTPConnectionPool(host='chrome-scan', port=4444): Max retries exceeded with url: /wd/hub/session (Caused by NewConnectionError('<urllib3.connection.HTTPConnection object at 0x000001DCAFD710B8>: Failed to establish a new connection: [Errno 11001] getaddrinfo failed'))
2019-07-08 16:25:44 logger.py[line:90] ERROR HTTPConnectionPool(host='chrome-scan', port=4444): Max retries exceeded with url: /wd/hub/session (Caused by NewConnectionError('<urllib3.connection.HTTPConnection object at 0x000001DCAFD711D0>: Failed to establish a new connection: [Errno 11001] getaddrinfo failed'))
2019-07-08 16:25:49 logger.py[line:90] ERROR 请检查好Chrome环境！
2019-07-08 16:25:49 logger.py[line:90] ERROR 请检查好Chrome环境！
2019-07-08 16:25:49 logger.py[line:90] ERROR 请检查好Chrome环境！
2019-07-08 16:25:49 logger.py[line:90] ERROR 请检查好Chrome环境！
2019-07-08 16:25:50 logger.py[line:96] DEBUG =================扫描程序结束==========================
2019-07-08 16:26:26 logger.py[line:96] DEBUG =================扫描程序开始==========================
2019-07-08 16:27:04 logger.py[line:90] ERROR HTTPConnectionPool(host='chrome-scan', port=4444): Max retries exceeded with url: /wd/hub/session (Caused by NewConnectionError('<urllib3.connection.HTTPConnection object at 0x00000217EA2D9518>: Failed to establish a new connection: [Errno 11001] getaddrinfo failed'))
2019-07-08 16:27:08 logger.py[line:90] ERROR HTTPConnectionPool(host='chrome-scan', port=4444): Max retries exceeded with url: /wd/hub/session (Caused by NewConnectionError('<urllib3.connection.HTTPConnection object at 0x00000217EA2D90B8>: Failed to establish a new connection: [Errno 11001] getaddrinfo failed'))
2019-07-08 16:27:13 logger.py[line:90] ERROR HTTPConnectionPool(host='chrome-scan', port=4444): Max retries exceeded with url: /wd/hub/session (Caused by NewConnectionError('<urllib3.connection.HTTPConnection object at 0x00000217EA2DD668>: Failed to establish a new connection: [Errno 11001] getaddrinfo failed'))
2019-07-08 16:27:15 logger.py[line:90] ERROR HTTPConnectionPool(host='chrome-scan', port=4444): Max retries exceeded with url: /wd/hub/session (Caused by NewConnectionError('<urllib3.connection.HTTPConnection object at 0x00000217EA2DD898>: Failed to establish a new connection: [Errno 11001] getaddrinfo failed'))
2019-07-08 16:27:19 logger.py[line:90] ERROR 请检查好Chrome环境！
2019-07-08 16:27:19 logger.py[line:90] ERROR 请检查好Chrome环境！
2019-07-08 16:27:20 logger.py[line:90] ERROR 请检查好Chrome环境！
2019-07-08 16:27:20 logger.py[line:90] ERROR 请检查好Chrome环境！
2019-07-08 16:27:20 logger.py[line:96] DEBUG =================扫描程序结束==========================
2019-07-08 16:27:57 logger.py[line:96] DEBUG =================扫描程序开始==========================
2019-07-08 16:28:21 logger.py[line:90] ERROR HTTPConnectionPool(host='chrome-scan', port=4444): Max retries exceeded with url: /wd/hub/session (Caused by NewConnectionError('<urllib3.connection.HTTPConnection object at 0x0000017BE01BE048>: Failed to establish a new connection: [Errno 11001] getaddrinfo failed'))
2019-07-08 16:28:23 logger.py[line:90] ERROR HTTPConnectionPool(host='chrome-scan', port=4444): Max retries exceeded with url: /wd/hub/session (Caused by NewConnectionError('<urllib3.connection.HTTPConnection object at 0x0000017BE01BEDA0>: Failed to establish a new connection: [Errno 11001] getaddrinfo failed'))
2019-07-08 16:28:28 logger.py[line:90] ERROR 请检查好Chrome环境！
2019-07-08 16:28:28 logger.py[line:90] ERROR 请检查好Chrome环境！
2019-07-08 16:37:15 logger.py[line:96] DEBUG =================扫描程序开始==========================
2019-07-08 16:37:41 logger.py[line:90] ERROR HTTPConnectionPool(host='chrome-scan', port=4444): Max retries exceeded with url: /wd/hub/session (Caused by NewConnectionError('<urllib3.connection.HTTPConnection object at 0x000001309A3EAF28>: Failed to establish a new connection: [Errno 11001] getaddrinfo failed'))
2019-07-08 16:38:04 logger.py[line:90] ERROR HTTPConnectionPool(host='chrome-scan', port=4444): Max retries exceeded with url: /wd/hub/session (Caused by NewConnectionError('<urllib3.connection.HTTPConnection object at 0x000001309A252978>: Failed to establish a new connection: [Errno 11001] getaddrinfo failed'))
2019-07-08 16:38:06 logger.py[line:90] ERROR HTTPConnectionPool(host='chrome-scan', port=4444): Max retries exceeded with url: /wd/hub/session (Caused by NewConnectionError('<urllib3.connection.HTTPConnection object at 0x000001309A3BC7B8>: Failed to establish a new connection: [Errno 11001] getaddrinfo failed'))
2019-07-08 16:38:10 logger.py[line:90] ERROR 请检查好Chrome环境！
2019-07-08 16:38:15 logger.py[line:90] ERROR HTTPConnectionPool(host='chrome-scan', port=4444): Max retries exceeded with url: /wd/hub/session (Caused by NewConnectionError('<urllib3.connection.HTTPConnection object at 0x000001309A273710>: Failed to establish a new connection: [Errno 11001] getaddrinfo failed'))
2019-07-08 16:38:18 logger.py[line:90] ERROR 请检查好Chrome环境！
2019-07-08 16:38:18 logger.py[line:90] ERROR 请检查好Chrome环境！
2019-07-08 16:38:20 logger.py[line:90] ERROR 请检查好Chrome环境！
2019-07-08 16:38:25 logger.py[line:96] DEBUG =================扫描程序结束==========================
2019-07-08 17:01:27 logger.py[line:96] DEBUG =================扫描程序开始==========================
2019-07-08 17:02:20 logger.py[line:90] ERROR HTTPConnectionPool(host='chrome-scan', port=4444): Max retries exceeded with url: /wd/hub/session (Caused by NewConnectionError('<urllib3.connection.HTTPConnection object at 0x00000223D14B47F0>: Failed to establish a new connection: [Errno 11001] getaddrinfo failed'))
2019-07-08 17:02:22 logger.py[line:90] ERROR HTTPConnectionPool(host='chrome-scan', port=4444): Max retries exceeded with url: /wd/hub/session (Caused by NewConnectionError('<urllib3.connection.HTTPConnection object at 0x00000223D138F780>: Failed to establish a new connection: [Errno 11001] getaddrinfo failed'))
2019-07-08 17:02:25 logger.py[line:90] ERROR HTTPConnectionPool(host='chrome-scan', port=4444): Max retries exceeded with url: /wd/hub/session (Caused by NewConnectionError('<urllib3.connection.HTTPConnection object at 0x00000223D138F710>: Failed to establish a new connection: [Errno 11001] getaddrinfo failed'))
2019-07-08 17:02:36 logger.py[line:90] ERROR HTTPConnectionPool(host='chrome-scan', port=4444): Max retries exceeded with url: /wd/hub/session (Caused by NewConnectionError('<urllib3.connection.HTTPConnection object at 0x00000223D13625F8>: Failed to establish a new connection: [Errno 11001] getaddrinfo failed'))
2019-07-08 17:02:38 logger.py[line:90] ERROR 请检查好Chrome环境！
2019-07-08 17:02:38 logger.py[line:90] ERROR 请检查好Chrome环境！
2019-07-08 17:02:38 logger.py[line:90] ERROR 请检查好Chrome环境！
2019-07-08 17:02:40 logger.py[line:90] ERROR 请检查好Chrome环境！
2019-07-08 17:02:46 logger.py[line:96] DEBUG =================扫描程序结束==========================
