2019-07-10 09:03:44 logger.py[line:96] DEBUG =================扫描程序开始==========================
2019-07-10 09:04:19 logger.py[line:90] ERROR HTTPConnectionPool(host='chrome-scan', port=4444): Max retries exceeded with url: /wd/hub/session (Caused by NewConnectionError('<urllib3.connection.HTTPConnection object at 0x000001CC67117DD8>: Failed to establish a new connection: [Errno 11001] getaddrinfo failed'))
2019-07-10 09:04:24 logger.py[line:90] ERROR 请检查好Chrome环境！
2019-07-10 09:04:45 logger.py[line:90] ERROR Message: no such element: Unable to locate element: {"method":"css selector","selector":"#kw"}
  (Session info: chrome=75.0.3770.100)
  (Driver info: chromedriver=2.37.544315 (730aa6a5fdba159ac9f4c1e8cbc59bf1b5ce12b7),platform=Windows NT 10.0.14393 x86_64)

2019-07-10 09:05:15 logger.py[line:90] ERROR HTTPConnectionPool(host='chrome-scan', port=4444): Max retries exceeded with url: /wd/hub/session (Caused by NewConnectionError('<urllib3.connection.HTTPConnection object at 0x000001CC672C9AC8>: Failed to establish a new connection: [Errno 11001] getaddrinfo failed'))
2019-07-10 09:05:19 logger.py[line:90] ERROR 请检查好Chrome环境！
2019-07-10 09:05:26 logger.py[line:90] ERROR Message: no such element: Unable to locate element: {"method":"css selector","selector":"#kw"}
  (Session info: chrome=75.0.3770.100)
  (Driver info: chromedriver=2.37.544315 (730aa6a5fdba159ac9f4c1e8cbc59bf1b5ce12b7),platform=Windows NT 10.0.14393 x86_64)

2019-07-10 09:06:10 logger.py[line:90] ERROR HTTPConnectionPool(host='chrome-scan', port=4444): Max retries exceeded with url: /wd/hub/session (Caused by NewConnectionError('<urllib3.connection.HTTPConnection object at 0x000001CC673484E0>: Failed to establish a new connection: [Errno 11001] getaddrinfo failed'))
2019-07-10 09:06:14 logger.py[line:90] ERROR 请检查好Chrome环境！
2019-07-10 09:06:43 logger.py[line:90] ERROR Message: unknown error: Element is not clickable at point (1026, 39)
  (Session info: chrome=75.0.3770.100)
  (Driver info: chromedriver=2.37.544315 (730aa6a5fdba159ac9f4c1e8cbc59bf1b5ce12b7),platform=Windows NT 10.0.14393 x86_64)

2019-07-10 09:06:55 logger.py[line:96] DEBUG =================扫描程序结束==========================
2019-07-10 11:31:15 logger.py[line:96] DEBUG =================扫描程序开始==========================
2019-07-10 11:32:17 logger.py[line:90] ERROR HTTPConnectionPool(host='chrome-scan', port=4444): Max retries exceeded with url: /wd/hub/session (Caused by NewConnectionError('<urllib3.connection.HTTPConnection object at 0x0000025B90BC95C0>: Failed to establish a new connection: [Errno 11001] getaddrinfo failed'))
2019-07-10 11:32:28 logger.py[line:90] ERROR 请检查好Chrome环境！
2019-07-10 11:32:28 logger.py[line:96] DEBUG =================扫描程序结束==========================
2019-07-10 11:44:46 logger.py[line:96] DEBUG =================扫描程序开始==========================
2019-07-10 11:45:14 logger.py[line:90] ERROR HTTPConnectionPool(host='chrome-scan', port=4444): Max retries exceeded with url: /wd/hub/session (Caused by NewConnectionError('<urllib3.connection.HTTPConnection object at 0x00000205D0FF8898>: Failed to establish a new connection: [Errno 11001] getaddrinfo failed'))
2019-07-10 11:45:18 logger.py[line:90] ERROR 请检查好Chrome环境！
2019-07-10 11:45:25 logger.py[line:90] ERROR Message: no such element: Unable to locate element: {"method":"css selector","selector":"#kw"}
  (Session info: chrome=75.0.3770.100)
  (Driver info: chromedriver=2.37.544315 (730aa6a5fdba159ac9f4c1e8cbc59bf1b5ce12b7),platform=Windows NT 10.0.14393 x86_64)

2019-07-10 11:46:08 logger.py[line:90] ERROR HTTPConnectionPool(host='chrome-scan', port=4444): Max retries exceeded with url: /wd/hub/session (Caused by NewConnectionError('<urllib3.connection.HTTPConnection object at 0x00000205D1272D68>: Failed to establish a new connection: [Errno 11001] getaddrinfo failed'))
2019-07-10 11:46:13 logger.py[line:90] ERROR 请检查好Chrome环境！
2019-07-10 11:46:19 logger.py[line:90] ERROR Message: no such element: Unable to locate element: {"method":"css selector","selector":"#kw"}
  (Session info: chrome=75.0.3770.100)
  (Driver info: chromedriver=2.37.544315 (730aa6a5fdba159ac9f4c1e8cbc59bf1b5ce12b7),platform=Windows NT 10.0.14393 x86_64)

2019-07-10 11:46:33 logger.py[line:90] ERROR HTTPConnectionPool(host='chrome-scan', port=4444): Max retries exceeded with url: /wd/hub/session (Caused by NewConnectionError('<urllib3.connection.HTTPConnection object at 0x00000205D1225D30>: Failed to establish a new connection: [Errno 11001] getaddrinfo failed'))
2019-07-10 11:46:37 logger.py[line:90] ERROR 请检查好Chrome环境！
2019-07-10 11:47:23 logger.py[line:90] ERROR list index out of range
2019-07-10 11:47:36 logger.py[line:96] DEBUG =================扫描程序结束==========================
2019-07-10 11:47:49 logger.py[line:96] DEBUG =================扫描程序开始==========================
2019-07-10 11:48:00 logger.py[line:90] ERROR HTTPConnectionPool(host='chrome-scan', port=4444): Max retries exceeded with url: /wd/hub/session (Caused by NewConnectionError('<urllib3.connection.HTTPConnection object at 0x00000151FFD18438>: Failed to establish a new connection: [Errno 11001] getaddrinfo failed'))
2019-07-10 11:48:05 logger.py[line:90] ERROR 请检查好Chrome环境！
2019-07-10 11:48:21 logger.py[line:90] ERROR Message: unknown error: Element is not clickable at point (1026, 39)
  (Session info: chrome=75.0.3770.100)
  (Driver info: chromedriver=2.37.544315 (730aa6a5fdba159ac9f4c1e8cbc59bf1b5ce12b7),platform=Windows NT 10.0.14393 x86_64)

2019-07-10 11:48:25 logger.py[line:96] DEBUG =================扫描程序结束==========================
2019-07-10 11:49:35 logger.py[line:96] DEBUG =================扫描程序开始==========================
2019-07-10 11:50:14 logger.py[line:90] ERROR HTTPConnectionPool(host='chrome-scan', port=4444): Max retries exceeded with url: /wd/hub/session (Caused by NewConnectionError('<urllib3.connection.HTTPConnection object at 0x0000019BDA159860>: Failed to establish a new connection: [Errno 11001] getaddrinfo failed'))
2019-07-10 11:50:16 logger.py[line:90] ERROR HTTPConnectionPool(host='chrome-scan', port=4444): Max retries exceeded with url: /wd/hub/session (Caused by NewConnectionError('<urllib3.connection.HTTPConnection object at 0x0000019BDA159978>: Failed to establish a new connection: [Errno 11001] getaddrinfo failed'))
2019-07-10 11:50:18 logger.py[line:90] ERROR HTTPConnectionPool(host='chrome-scan', port=4444): Max retries exceeded with url: /wd/hub/session (Caused by NewConnectionError('<urllib3.connection.HTTPConnection object at 0x0000019BDA159A90>: Failed to establish a new connection: [Errno 11001] getaddrinfo failed'))
2019-07-10 11:50:20 logger.py[line:90] ERROR HTTPConnectionPool(host='chrome-scan', port=4444): Max retries exceeded with url: /wd/hub/session (Caused by NewConnectionError('<urllib3.connection.HTTPConnection object at 0x0000019BDA159BA8>: Failed to establish a new connection: [Errno 11001] getaddrinfo failed'))
2019-07-10 11:50:25 logger.py[line:90] ERROR 请检查好Chrome环境！
2019-07-10 11:50:25 logger.py[line:90] ERROR 请检查好Chrome环境！
2019-07-10 11:50:25 logger.py[line:90] ERROR 请检查好Chrome环境！
2019-07-10 11:50:25 logger.py[line:90] ERROR 请检查好Chrome环境！
2019-07-10 11:50:39 logger.py[line:90] ERROR list index out of range
2019-07-10 11:50:43 logger.py[line:90] ERROR Message: unknown error: Element is not clickable at point (1026, 39)
  (Session info: chrome=75.0.3770.100)
  (Driver info: chromedriver=2.37.544315 (730aa6a5fdba159ac9f4c1e8cbc59bf1b5ce12b7),platform=Windows NT 10.0.14393 x86_64)

2019-07-10 11:50:45 logger.py[line:90] ERROR Message: unknown error: Element is not clickable at point (1026, 39)
  (Session info: chrome=75.0.3770.100)
  (Driver info: chromedriver=2.37.544315 (730aa6a5fdba159ac9f4c1e8cbc59bf1b5ce12b7),platform=Windows NT 10.0.14393 x86_64)

2019-07-10 11:51:00 logger.py[line:90] ERROR Message: unknown error: Element is not clickable at point (1026, 39)
  (Session info: chrome=75.0.3770.100)
  (Driver info: chromedriver=2.37.544315 (730aa6a5fdba159ac9f4c1e8cbc59bf1b5ce12b7),platform=Windows NT 10.0.14393 x86_64)

2019-07-10 11:51:04 logger.py[line:96] DEBUG =================扫描程序结束==========================
2019-07-10 11:52:54 logger.py[line:96] DEBUG =================扫描程序开始==========================
2019-07-10 11:53:32 logger.py[line:90] ERROR HTTPConnectionPool(host='chrome-scan', port=4444): Max retries exceeded with url: /wd/hub/session (Caused by NewConnectionError('<urllib3.connection.HTTPConnection object at 0x0000017EDD128278>: Failed to establish a new connection: [Errno 11001] getaddrinfo failed'))
2019-07-10 11:53:35 logger.py[line:90] ERROR HTTPConnectionPool(host='chrome-scan', port=4444): Max retries exceeded with url: /wd/hub/session (Caused by NewConnectionError('<urllib3.connection.HTTPConnection object at 0x0000017EDD128390>: Failed to establish a new connection: [Errno 11001] getaddrinfo failed'))
2019-07-10 11:53:37 logger.py[line:90] ERROR HTTPConnectionPool(host='chrome-scan', port=4444): Max retries exceeded with url: /wd/hub/session (Caused by NewConnectionError('<urllib3.connection.HTTPConnection object at 0x0000017EDD1284A8>: Failed to establish a new connection: [Errno 11001] getaddrinfo failed'))
2019-07-10 11:53:39 logger.py[line:90] ERROR HTTPConnectionPool(host='chrome-scan', port=4444): Max retries exceeded with url: /wd/hub/session (Caused by NewConnectionError('<urllib3.connection.HTTPConnection object at 0x0000017EDD1285C0>: Failed to establish a new connection: [Errno 11001] getaddrinfo failed'))
2019-07-10 11:53:44 logger.py[line:90] ERROR 请检查好Chrome环境！
2019-07-10 11:53:44 logger.py[line:90] ERROR 请检查好Chrome环境！
2019-07-10 11:53:44 logger.py[line:90] ERROR 请检查好Chrome环境！
2019-07-10 11:53:44 logger.py[line:90] ERROR 请检查好Chrome环境！
2019-07-10 11:53:54 logger.py[line:90] ERROR list index out of range
2019-07-10 11:53:59 logger.py[line:90] ERROR Message: unknown error: Element is not clickable at point (1026, 39)
  (Session info: chrome=75.0.3770.100)
  (Driver info: chromedriver=2.37.544315 (730aa6a5fdba159ac9f4c1e8cbc59bf1b5ce12b7),platform=Windows NT 10.0.14393 x86_64)

2019-07-10 11:54:00 logger.py[line:90] ERROR Message: unknown error: Element is not clickable at point (1026, 39)
  (Session info: chrome=75.0.3770.100)
  (Driver info: chromedriver=2.37.544315 (730aa6a5fdba159ac9f4c1e8cbc59bf1b5ce12b7),platform=Windows NT 10.0.14393 x86_64)

2019-07-10 11:54:10 logger.py[line:90] ERROR Message: unknown error: Element <a data-click="{
			'F':'778717EA',
			'F1':'9D73F1C4',
			'F2':'4CA6DE6B',
			'F3':'54E52437',
			'T':'1562730843',
						'y':'CF7FE5AB'
			 
									}" href="http://www.baidu.com/link?url=u-wWOXeaIGddWC5USsU9viYLw9vfcDBwcF2o2ZstDja" target="_blank">...</a> is not clickable at point (137, 230). Other element would receive the click: <div class="c-abstract">...</div>
  (Session info: chrome=75.0.3770.100)
  (Driver info: chromedriver=2.37.544315 (730aa6a5fdba159ac9f4c1e8cbc59bf1b5ce12b7),platform=Windows NT 10.0.14393 x86_64)

2019-07-10 11:54:14 logger.py[line:96] DEBUG =================扫描程序结束==========================
2019-07-10 11:54:29 logger.py[line:96] DEBUG =================扫描程序开始==========================
2019-07-10 11:55:07 logger.py[line:90] ERROR HTTPConnectionPool(host='chrome-scan', port=4444): Max retries exceeded with url: /wd/hub/session (Caused by NewConnectionError('<urllib3.connection.HTTPConnection object at 0x000001C9B2ABF2E8>: Failed to establish a new connection: [Errno 11001] getaddrinfo failed'))
2019-07-10 11:55:09 logger.py[line:90] ERROR HTTPConnectionPool(host='chrome-scan', port=4444): Max retries exceeded with url: /wd/hub/session (Caused by NewConnectionError('<urllib3.connection.HTTPConnection object at 0x000001C9B2ABF400>: Failed to establish a new connection: [Errno 11001] getaddrinfo failed'))
2019-07-10 11:55:12 logger.py[line:90] ERROR HTTPConnectionPool(host='chrome-scan', port=4444): Max retries exceeded with url: /wd/hub/session (Caused by NewConnectionError('<urllib3.connection.HTTPConnection object at 0x000001C9B2ABF518>: Failed to establish a new connection: [Errno 11001] getaddrinfo failed'))
2019-07-10 11:55:14 logger.py[line:90] ERROR HTTPConnectionPool(host='chrome-scan', port=4444): Max retries exceeded with url: /wd/hub/session (Caused by NewConnectionError('<urllib3.connection.HTTPConnection object at 0x000001C9B2ABF630>: Failed to establish a new connection: [Errno 11001] getaddrinfo failed'))
2019-07-10 11:55:19 logger.py[line:90] ERROR 请检查好Chrome环境！
2019-07-10 11:55:19 logger.py[line:90] ERROR 请检查好Chrome环境！
2019-07-10 11:55:19 logger.py[line:90] ERROR 请检查好Chrome环境！
2019-07-10 11:55:19 logger.py[line:90] ERROR 请检查好Chrome环境！
2019-07-10 11:55:28 logger.py[line:90] ERROR list index out of range
2019-07-10 11:55:33 logger.py[line:90] ERROR Message: unknown error: Element is not clickable at point (1026, 39)
  (Session info: chrome=75.0.3770.100)
  (Driver info: chromedriver=2.37.544315 (730aa6a5fdba159ac9f4c1e8cbc59bf1b5ce12b7),platform=Windows NT 10.0.14393 x86_64)

2019-07-10 11:55:33 logger.py[line:90] ERROR Message: unknown error: Element is not clickable at point (1026, 39)
  (Session info: chrome=75.0.3770.100)
  (Driver info: chromedriver=2.37.544315 (730aa6a5fdba159ac9f4c1e8cbc59bf1b5ce12b7),platform=Windows NT 10.0.14393 x86_64)

2019-07-10 11:55:44 logger.py[line:90] ERROR Message: unknown error: Element is not clickable at point (1026, 39)
  (Session info: chrome=75.0.3770.100)
  (Driver info: chromedriver=2.37.544315 (730aa6a5fdba159ac9f4c1e8cbc59bf1b5ce12b7),platform=Windows NT 10.0.14393 x86_64)

2019-07-10 11:55:48 logger.py[line:96] DEBUG =================扫描程序结束==========================
2019-07-10 11:56:14 logger.py[line:96] DEBUG =================扫描程序开始==========================
2019-07-10 11:56:52 logger.py[line:90] ERROR HTTPConnectionPool(host='chrome-scan', port=4444): Max retries exceeded with url: /wd/hub/session (Caused by NewConnectionError('<urllib3.connection.HTTPConnection object at 0x000001A2B20E5390>: Failed to establish a new connection: [Errno 11001] getaddrinfo failed'))
2019-07-10 11:56:54 logger.py[line:90] ERROR HTTPConnectionPool(host='chrome-scan', port=4444): Max retries exceeded with url: /wd/hub/session (Caused by NewConnectionError('<urllib3.connection.HTTPConnection object at 0x000001A2B20E54A8>: Failed to establish a new connection: [Errno 11001] getaddrinfo failed'))
2019-07-10 11:56:57 logger.py[line:90] ERROR HTTPConnectionPool(host='chrome-scan', port=4444): Max retries exceeded with url: /wd/hub/session (Caused by NewConnectionError('<urllib3.connection.HTTPConnection object at 0x000001A2B20E55C0>: Failed to establish a new connection: [Errno 11001] getaddrinfo failed'))
2019-07-10 11:56:59 logger.py[line:90] ERROR HTTPConnectionPool(host='chrome-scan', port=4444): Max retries exceeded with url: /wd/hub/session (Caused by NewConnectionError('<urllib3.connection.HTTPConnection object at 0x000001A2B20E56D8>: Failed to establish a new connection: [Errno 11001] getaddrinfo failed'))
2019-07-10 11:57:04 logger.py[line:90] ERROR 请检查好Chrome环境！
2019-07-10 11:57:04 logger.py[line:90] ERROR 请检查好Chrome环境！
2019-07-10 11:57:04 logger.py[line:90] ERROR 请检查好Chrome环境！
2019-07-10 11:57:04 logger.py[line:90] ERROR 请检查好Chrome环境！
2019-07-10 11:57:18 logger.py[line:90] ERROR list index out of range
2019-07-10 11:58:14 logger.py[line:90] ERROR Message: unknown error: Element is not clickable at point (1026, 39)
  (Session info: chrome=75.0.3770.100)
  (Driver info: chromedriver=2.37.544315 (730aa6a5fdba159ac9f4c1e8cbc59bf1b5ce12b7),platform=Windows NT 10.0.14393 x86_64)

2019-07-10 11:58:14 logger.py[line:90] ERROR Message: unknown error: Element is not clickable at point (1026, 39)
  (Session info: chrome=75.0.3770.100)
  (Driver info: chromedriver=2.37.544315 (730aa6a5fdba159ac9f4c1e8cbc59bf1b5ce12b7),platform=Windows NT 10.0.14393 x86_64)

2019-07-10 11:58:18 logger.py[line:96] DEBUG =================扫描程序结束==========================
2019-07-10 13:33:55 logger.py[line:96] DEBUG =================扫描程序开始==========================
2019-07-10 13:34:33 logger.py[line:90] ERROR HTTPConnectionPool(host='chrome-scan', port=4444): Max retries exceeded with url: /wd/hub/session (Caused by NewConnectionError('<urllib3.connection.HTTPConnection object at 0x00000273B2BFE3C8>: Failed to establish a new connection: [Errno 11001] getaddrinfo failed'))
2019-07-10 13:34:35 logger.py[line:90] ERROR HTTPConnectionPool(host='chrome-scan', port=4444): Max retries exceeded with url: /wd/hub/session (Caused by NewConnectionError('<urllib3.connection.HTTPConnection object at 0x00000273B2BFE4E0>: Failed to establish a new connection: [Errno 11001] getaddrinfo failed'))
2019-07-10 13:34:37 logger.py[line:90] ERROR HTTPConnectionPool(host='chrome-scan', port=4444): Max retries exceeded with url: /wd/hub/session (Caused by NewConnectionError('<urllib3.connection.HTTPConnection object at 0x00000273B2BFE5F8>: Failed to establish a new connection: [Errno 11001] getaddrinfo failed'))
2019-07-10 13:34:40 logger.py[line:90] ERROR HTTPConnectionPool(host='chrome-scan', port=4444): Max retries exceeded with url: /wd/hub/session (Caused by NewConnectionError('<urllib3.connection.HTTPConnection object at 0x00000273B2BFE710>: Failed to establish a new connection: [Errno 11001] getaddrinfo failed'))
2019-07-10 13:34:44 logger.py[line:90] ERROR 请检查好Chrome环境！
2019-07-10 13:34:45 logger.py[line:90] ERROR 请检查好Chrome环境！
2019-07-10 13:34:45 logger.py[line:90] ERROR 请检查好Chrome环境！
2019-07-10 13:34:45 logger.py[line:90] ERROR 请检查好Chrome环境！
2019-07-10 13:34:54 logger.py[line:90] ERROR list index out of range
2019-07-10 13:34:58 logger.py[line:90] ERROR Message: unknown error: Element is not clickable at point (1026, 39)
  (Session info: chrome=75.0.3770.100)
  (Driver info: chromedriver=2.37.544315 (730aa6a5fdba159ac9f4c1e8cbc59bf1b5ce12b7),platform=Windows NT 10.0.14393 x86_64)

2019-07-10 13:34:58 logger.py[line:90] ERROR Message: unknown error: Element is not clickable at point (1026, 39)
  (Session info: chrome=75.0.3770.100)
  (Driver info: chromedriver=2.37.544315 (730aa6a5fdba159ac9f4c1e8cbc59bf1b5ce12b7),platform=Windows NT 10.0.14393 x86_64)

2019-07-10 13:35:10 logger.py[line:90] ERROR Message: unknown error: Element is not clickable at point (1026, 39)
  (Session info: chrome=75.0.3770.100)
  (Driver info: chromedriver=2.37.544315 (730aa6a5fdba159ac9f4c1e8cbc59bf1b5ce12b7),platform=Windows NT 10.0.14393 x86_64)

2019-07-10 13:35:14 logger.py[line:96] DEBUG =================扫描程序结束==========================
2019-07-10 13:40:57 logger.py[line:96] DEBUG =================扫描程序开始==========================
2019-07-10 13:43:05 logger.py[line:96] DEBUG =================扫描程序开始==========================
2019-07-10 13:48:17 logger.py[line:96] DEBUG =================扫描程序开始==========================
2019-07-10 13:48:49 logger.py[line:96] DEBUG =================扫描程序开始==========================
2019-07-10 13:50:17 logger.py[line:90] ERROR HTTPConnectionPool(host='chrome-scan', port=4444): Max retries exceeded with url: /wd/hub/session (Caused by NewConnectionError('<urllib3.connection.HTTPConnection object at 0x000001B10D50CC18>: Failed to establish a new connection: [Errno 11001] getaddrinfo failed'))
2019-07-10 13:50:19 logger.py[line:90] ERROR HTTPConnectionPool(host='chrome-scan', port=4444): Max retries exceeded with url: /wd/hub/session (Caused by NewConnectionError('<urllib3.connection.HTTPConnection object at 0x000001B10D50CD68>: Failed to establish a new connection: [Errno 11001] getaddrinfo failed'))
2019-07-10 13:50:22 logger.py[line:90] ERROR HTTPConnectionPool(host='chrome-scan', port=4444): Max retries exceeded with url: /wd/hub/session (Caused by NewConnectionError('<urllib3.connection.HTTPConnection object at 0x000001B10D52C1D0>: Failed to establish a new connection: [Errno 11001] getaddrinfo failed'))
2019-07-10 13:50:24 logger.py[line:90] ERROR HTTPConnectionPool(host='chrome-scan', port=4444): Max retries exceeded with url: /wd/hub/session (Caused by NewConnectionError('<urllib3.connection.HTTPConnection object at 0x000001B10D52C2B0>: Failed to establish a new connection: [Errno 11001] getaddrinfo failed'))
2019-07-10 13:50:26 logger.py[line:90] ERROR HTTPConnectionPool(host='chrome-scan', port=4444): Max retries exceeded with url: /wd/hub/session (Caused by NewConnectionError('<urllib3.connection.HTTPConnection object at 0x000001B10D52C358>: Failed to establish a new connection: [Errno 11001] getaddrinfo failed'))
2019-07-10 13:50:28 logger.py[line:90] ERROR HTTPConnectionPool(host='chrome-scan', port=4444): Max retries exceeded with url: /wd/hub/session (Caused by NewConnectionError('<urllib3.connection.HTTPConnection object at 0x000001B10D52C4A8>: Failed to establish a new connection: [Errno 11001] getaddrinfo failed'))
2019-07-10 13:50:31 logger.py[line:90] ERROR HTTPConnectionPool(host='chrome-scan', port=4444): Max retries exceeded with url: /wd/hub/session (Caused by NewConnectionError('<urllib3.connection.HTTPConnection object at 0x000001B10D52C5F8>: Failed to establish a new connection: [Errno 11001] getaddrinfo failed'))
2019-07-10 13:50:33 logger.py[line:90] ERROR HTTPConnectionPool(host='chrome-scan', port=4444): Max retries exceeded with url: /wd/hub/session (Caused by NewConnectionError('<urllib3.connection.HTTPConnection object at 0x000001B10D52C748>: Failed to establish a new connection: [Errno 11001] getaddrinfo failed'))
2019-07-10 13:50:38 logger.py[line:90] ERROR 请检查好Chrome环境！
2019-07-10 13:50:38 logger.py[line:90] ERROR 请检查好Chrome环境！
2019-07-10 13:50:38 logger.py[line:90] ERROR 请检查好Chrome环境！
2019-07-10 13:50:38 logger.py[line:90] ERROR 请检查好Chrome环境！
2019-07-10 13:50:38 logger.py[line:90] ERROR 请检查好Chrome环境！
2019-07-10 13:50:38 logger.py[line:90] ERROR 请检查好Chrome环境！
2019-07-10 13:50:38 logger.py[line:90] ERROR 请检查好Chrome环境！
2019-07-10 13:50:39 logger.py[line:90] ERROR 请检查好Chrome环境！
2019-07-10 13:50:55 logger.py[line:90] ERROR resolution_page() missing 1 required positional argument: 'keyword'
2019-07-10 13:50:56 logger.py[line:90] ERROR resolution_page() missing 1 required positional argument: 'keyword'
2019-07-10 13:50:56 logger.py[line:90] ERROR resolution_page() missing 1 required positional argument: 'keyword'
2019-07-10 13:50:58 logger.py[line:90] ERROR list index out of range
2019-07-10 13:50:59 logger.py[line:90] ERROR resolution_page() missing 1 required positional argument: 'keyword'
2019-07-10 13:50:59 logger.py[line:90] ERROR resolution_page() missing 1 required positional argument: 'keyword'
2019-07-10 13:51:00 logger.py[line:90] ERROR resolution_page() missing 1 required positional argument: 'keyword'
2019-07-10 13:51:00 logger.py[line:90] ERROR list index out of range
2019-07-10 13:51:00 logger.py[line:96] DEBUG =================扫描程序结束==========================
2019-07-10 13:51:37 logger.py[line:96] DEBUG =================扫描程序开始==========================
2019-07-10 13:52:28 logger.py[line:90] ERROR HTTPConnectionPool(host='chrome-scan', port=4444): Max retries exceeded with url: /wd/hub/session (Caused by NewConnectionError('<urllib3.connection.HTTPConnection object at 0x0000018C29F245F8>: Failed to establish a new connection: [Errno 11001] getaddrinfo failed'))
2019-07-10 13:52:30 logger.py[line:90] ERROR HTTPConnectionPool(host='chrome-scan', port=4444): Max retries exceeded with url: /wd/hub/session (Caused by NewConnectionError('<urllib3.connection.HTTPConnection object at 0x0000018C29F24748>: Failed to establish a new connection: [Errno 11001] getaddrinfo failed'))
2019-07-10 13:52:35 logger.py[line:90] ERROR HTTPConnectionPool(host='chrome-scan', port=4444): Max retries exceeded with url: /wd/hub/session (Caused by NewConnectionError('<urllib3.connection.HTTPConnection object at 0x0000018C29EDE1D0>: Failed to establish a new connection: [Errno 11001] getaddrinfo failed'))
2019-07-10 13:52:39 logger.py[line:90] ERROR 请检查好Chrome环境！
2019-07-10 13:52:39 logger.py[line:90] ERROR 请检查好Chrome环境！
2019-07-10 13:52:39 logger.py[line:90] ERROR 请检查好Chrome环境！
2019-07-10 13:52:52 logger.py[line:90] ERROR resolution_page() missing 1 required positional argument: 'keyword'
2019-07-10 13:52:52 logger.py[line:90] ERROR resolution_page() missing 1 required positional argument: 'keyword'
2019-07-10 13:53:19 logger.py[line:96] DEBUG =================扫描程序开始==========================
2019-07-10 13:54:29 logger.py[line:90] ERROR HTTPConnectionPool(host='chrome-scan', port=4444): Max retries exceeded with url: /wd/hub/session (Caused by NewConnectionError('<urllib3.connection.HTTPConnection object at 0x0000020568FBACC0>: Failed to establish a new connection: [Errno 11001] getaddrinfo failed'))
2019-07-10 13:54:41 logger.py[line:90] ERROR HTTPConnectionPool(host='chrome-scan', port=4444): Max retries exceeded with url: /wd/hub/session (Caused by NewConnectionError('<urllib3.connection.HTTPConnection object at 0x0000020568FE42E8>: Failed to establish a new connection: [Errno 11001] getaddrinfo failed'))
2019-07-10 13:54:43 logger.py[line:90] ERROR HTTPConnectionPool(host='chrome-scan', port=4444): Max retries exceeded with url: /wd/hub/session (Caused by NewConnectionError('<urllib3.connection.HTTPConnection object at 0x0000020568FE4438>: Failed to establish a new connection: [Errno 11001] getaddrinfo failed'))
2019-07-10 13:54:45 logger.py[line:90] ERROR HTTPConnectionPool(host='chrome-scan', port=4444): Max retries exceeded with url: /wd/hub/session (Caused by NewConnectionError('<urllib3.connection.HTTPConnection object at 0x0000020568FE4588>: Failed to establish a new connection: [Errno 11001] getaddrinfo failed'))
2019-07-10 13:54:47 logger.py[line:90] ERROR HTTPConnectionPool(host='chrome-scan', port=4444): Max retries exceeded with url: /wd/hub/session (Caused by NewConnectionError('<urllib3.connection.HTTPConnection object at 0x0000020568FE4940>: Failed to establish a new connection: [Errno 11001] getaddrinfo failed'))
2019-07-10 13:54:50 logger.py[line:90] ERROR HTTPConnectionPool(host='chrome-scan', port=4444): Max retries exceeded with url: /wd/hub/session (Caused by NewConnectionError('<urllib3.connection.HTTPConnection object at 0x0000020568F39128>: Failed to establish a new connection: [Errno 11001] getaddrinfo failed'))
2019-07-10 13:54:52 logger.py[line:90] ERROR HTTPConnectionPool(host='chrome-scan', port=4444): Max retries exceeded with url: /wd/hub/session (Caused by NewConnectionError('<urllib3.connection.HTTPConnection object at 0x0000020568EC2D68>: Failed to establish a new connection: [Errno 11001] getaddrinfo failed'))
2019-07-10 13:54:54 logger.py[line:90] ERROR HTTPConnectionPool(host='chrome-scan', port=4444): Max retries exceeded with url: /wd/hub/session (Caused by NewConnectionError('<urllib3.connection.HTTPConnection object at 0x0000020568EC26A0>: Failed to establish a new connection: [Errno 11001] getaddrinfo failed'))
2019-07-10 13:54:58 logger.py[line:90] ERROR 请检查好Chrome环境！
2019-07-10 13:54:59 logger.py[line:90] ERROR 请检查好Chrome环境！
2019-07-10 13:54:59 logger.py[line:90] ERROR 请检查好Chrome环境！
2019-07-10 13:54:59 logger.py[line:90] ERROR 请检查好Chrome环境！
2019-07-10 13:54:59 logger.py[line:90] ERROR 请检查好Chrome环境！
2019-07-10 13:55:00 logger.py[line:90] ERROR 请检查好Chrome环境！
2019-07-10 13:55:00 logger.py[line:90] ERROR 请检查好Chrome环境！
2019-07-10 13:55:00 logger.py[line:90] ERROR 请检查好Chrome环境！
2019-07-10 13:55:10 logger.py[line:90] ERROR resolution_page() missing 1 required positional argument: 'keyword'
2019-07-10 13:55:12 logger.py[line:90] ERROR resolution_page() missing 1 required positional argument: 'keyword'
2019-07-10 13:55:14 logger.py[line:90] ERROR resolution_page() missing 1 required positional argument: 'keyword'
2019-07-10 13:55:16 logger.py[line:90] ERROR list index out of range
2019-07-10 13:55:16 logger.py[line:90] ERROR resolution_page() missing 1 required positional argument: 'keyword'
2019-07-10 13:55:19 logger.py[line:90] ERROR resolution_page() missing 1 required positional argument: 'keyword'
2019-07-10 13:55:19 logger.py[line:90] ERROR list index out of range
2019-07-10 13:55:19 logger.py[line:90] ERROR resolution_page() missing 1 required positional argument: 'keyword'
2019-07-10 13:55:21 logger.py[line:90] ERROR HTTPConnectionPool(host='chrome-scan', port=4444): Max retries exceeded with url: /wd/hub/session (Caused by NewConnectionError('<urllib3.connection.HTTPConnection object at 0x000002056A543A90>: Failed to establish a new connection: [Errno 11001] getaddrinfo failed'))
2019-07-10 13:56:27 logger.py[line:96] DEBUG =================扫描程序开始==========================
2019-07-10 13:57:41 logger.py[line:90] ERROR HTTPConnectionPool(host='chrome-scan', port=4444): Max retries exceeded with url: /wd/hub/session (Caused by NewConnectionError('<urllib3.connection.HTTPConnection object at 0x000002CCDC2B56A0>: Failed to establish a new connection: [Errno 11001] getaddrinfo failed'))
2019-07-10 13:57:44 logger.py[line:90] ERROR HTTPConnectionPool(host='chrome-scan', port=4444): Max retries exceeded with url: /wd/hub/session (Caused by NewConnectionError('<urllib3.connection.HTTPConnection object at 0x000002CCDC2B57B8>: Failed to establish a new connection: [Errno 11001] getaddrinfo failed'))
2019-07-10 13:57:46 logger.py[line:90] ERROR HTTPConnectionPool(host='chrome-scan', port=4444): Max retries exceeded with url: /wd/hub/session (Caused by NewConnectionError('<urllib3.connection.HTTPConnection object at 0x000002CCDC2B58D0>: Failed to establish a new connection: [Errno 11001] getaddrinfo failed'))
2019-07-10 13:57:48 logger.py[line:90] ERROR HTTPConnectionPool(host='chrome-scan', port=4444): Max retries exceeded with url: /wd/hub/session (Caused by NewConnectionError('<urllib3.connection.HTTPConnection object at 0x000002CCDC2B59E8>: Failed to establish a new connection: [Errno 11001] getaddrinfo failed'))
2019-07-10 13:57:50 logger.py[line:90] ERROR HTTPConnectionPool(host='chrome-scan', port=4444): Max retries exceeded with url: /wd/hub/session (Caused by NewConnectionError('<urllib3.connection.HTTPConnection object at 0x000002CCDC2B5B00>: Failed to establish a new connection: [Errno 11001] getaddrinfo failed'))
2019-07-10 13:57:53 logger.py[line:90] ERROR HTTPConnectionPool(host='chrome-scan', port=4444): Max retries exceeded with url: /wd/hub/session (Caused by NewConnectionError('<urllib3.connection.HTTPConnection object at 0x000002CCDC2B5C18>: Failed to establish a new connection: [Errno 11001] getaddrinfo failed'))
2019-07-10 13:57:55 logger.py[line:90] ERROR HTTPConnectionPool(host='chrome-scan', port=4444): Max retries exceeded with url: /wd/hub/session (Caused by NewConnectionError('<urllib3.connection.HTTPConnection object at 0x000002CCDC2B5D30>: Failed to establish a new connection: [Errno 11001] getaddrinfo failed'))
2019-07-10 13:57:57 logger.py[line:90] ERROR HTTPConnectionPool(host='chrome-scan', port=4444): Max retries exceeded with url: /wd/hub/session (Caused by NewConnectionError('<urllib3.connection.HTTPConnection object at 0x000002CCDC2B5E48>: Failed to establish a new connection: [Errno 11001] getaddrinfo failed'))
2019-07-10 13:58:02 logger.py[line:90] ERROR 请检查好Chrome环境！
2019-07-10 13:58:03 logger.py[line:90] ERROR 请检查好Chrome环境！
2019-07-10 13:58:03 logger.py[line:90] ERROR 请检查好Chrome环境！
2019-07-10 13:58:03 logger.py[line:90] ERROR 请检查好Chrome环境！
2019-07-10 13:58:03 logger.py[line:90] ERROR 请检查好Chrome环境！
2019-07-10 13:58:03 logger.py[line:90] ERROR 请检查好Chrome环境！
2019-07-10 13:58:03 logger.py[line:90] ERROR 请检查好Chrome环境！
2019-07-10 13:58:03 logger.py[line:90] ERROR 请检查好Chrome环境！
2019-07-10 13:58:22 logger.py[line:90] ERROR list index out of range
2019-07-10 13:58:27 logger.py[line:90] ERROR list index out of range
2019-07-10 13:58:38 logger.py[line:90] ERROR Message: unknown error: Element is not clickable at point (1026, 39)
  (Session info: chrome=75.0.3770.100)
  (Driver info: chromedriver=2.37.544315 (730aa6a5fdba159ac9f4c1e8cbc59bf1b5ce12b7),platform=Windows NT 10.0.14393 x86_64)

2019-07-10 13:58:39 logger.py[line:90] ERROR Message: unknown error: Element is not clickable at point (1026, 39)
  (Session info: chrome=75.0.3770.100)
  (Driver info: chromedriver=2.37.544315 (730aa6a5fdba159ac9f4c1e8cbc59bf1b5ce12b7),platform=Windows NT 10.0.14393 x86_64)

2019-07-10 13:58:57 logger.py[line:90] ERROR Message: unknown error: Element is not clickable at point (1026, 39)
  (Session info: chrome=75.0.3770.100)
  (Driver info: chromedriver=2.37.544315 (730aa6a5fdba159ac9f4c1e8cbc59bf1b5ce12b7),platform=Windows NT 10.0.14393 x86_64)

2019-07-10 14:00:56 logger.py[line:96] DEBUG =================扫描程序开始==========================
2019-07-10 14:02:34 logger.py[line:90] ERROR HTTPConnectionPool(host='chrome-scan', port=4444): Max retries exceeded with url: /wd/hub/session (Caused by NewConnectionError('<urllib3.connection.HTTPConnection object at 0x0000025D8EFEBAC8>: Failed to establish a new connection: [Errno 11001] getaddrinfo failed'))
2019-07-10 14:02:36 logger.py[line:90] ERROR HTTPConnectionPool(host='chrome-scan', port=4444): Max retries exceeded with url: /wd/hub/session (Caused by NewConnectionError('<urllib3.connection.HTTPConnection object at 0x0000025D8EFEBC18>: Failed to establish a new connection: [Errno 11001] getaddrinfo failed'))
2019-07-10 14:02:39 logger.py[line:90] ERROR HTTPConnectionPool(host='chrome-scan', port=4444): Max retries exceeded with url: /wd/hub/session (Caused by NewConnectionError('<urllib3.connection.HTTPConnection object at 0x0000025D8EFEBD68>: Failed to establish a new connection: [Errno 11001] getaddrinfo failed'))
2019-07-10 14:02:41 logger.py[line:90] ERROR HTTPConnectionPool(host='chrome-scan', port=4444): Max retries exceeded with url: /wd/hub/session (Caused by NewConnectionError('<urllib3.connection.HTTPConnection object at 0x0000025D8EFEBEB8>: Failed to establish a new connection: [Errno 11001] getaddrinfo failed'))
2019-07-10 14:02:43 logger.py[line:90] ERROR HTTPConnectionPool(host='chrome-scan', port=4444): Max retries exceeded with url: /wd/hub/session (Caused by NewConnectionError('<urllib3.connection.HTTPConnection object at 0x0000025D8F00C080>: Failed to establish a new connection: [Errno 11001] getaddrinfo failed'))
2019-07-10 14:02:45 logger.py[line:90] ERROR HTTPConnectionPool(host='chrome-scan', port=4444): Max retries exceeded with url: /wd/hub/session (Caused by NewConnectionError('<urllib3.connection.HTTPConnection object at 0x0000025D8F00C198>: Failed to establish a new connection: [Errno 11001] getaddrinfo failed'))
2019-07-10 14:02:48 logger.py[line:90] ERROR HTTPConnectionPool(host='chrome-scan', port=4444): Max retries exceeded with url: /wd/hub/session (Caused by NewConnectionError('<urllib3.connection.HTTPConnection object at 0x0000025D8F00C2E8>: Failed to establish a new connection: [Errno 11001] getaddrinfo failed'))
2019-07-10 14:02:50 logger.py[line:90] ERROR HTTPConnectionPool(host='chrome-scan', port=4444): Max retries exceeded with url: /wd/hub/session (Caused by NewConnectionError('<urllib3.connection.HTTPConnection object at 0x0000025D8F00C438>: Failed to establish a new connection: [Errno 11001] getaddrinfo failed'))
2019-07-10 14:02:55 logger.py[line:90] ERROR 请检查好Chrome环境！
2019-07-10 14:02:55 logger.py[line:90] ERROR 请检查好Chrome环境！
2019-07-10 14:02:55 logger.py[line:90] ERROR 请检查好Chrome环境！
2019-07-10 14:02:55 logger.py[line:90] ERROR 请检查好Chrome环境！
2019-07-10 14:02:55 logger.py[line:90] ERROR 请检查好Chrome环境！
2019-07-10 14:02:55 logger.py[line:90] ERROR 请检查好Chrome环境！
2019-07-10 14:02:55 logger.py[line:90] ERROR 请检查好Chrome环境！
2019-07-10 14:02:55 logger.py[line:90] ERROR 请检查好Chrome环境！
2019-07-10 14:03:10 logger.py[line:90] ERROR list index out of range
2019-07-10 14:03:27 logger.py[line:90] ERROR list index out of range
2019-07-10 14:06:29 logger.py[line:96] DEBUG =================扫描程序结束==========================
2019-07-10 14:08:41 logger.py[line:96] DEBUG =================扫描程序开始==========================
2019-07-10 14:09:56 logger.py[line:90] ERROR HTTPConnectionPool(host='chrome-scan', port=4444): Max retries exceeded with url: /wd/hub/session (Caused by NewConnectionError('<urllib3.connection.HTTPConnection object at 0x00000162EE91A550>: Failed to establish a new connection: [Errno 11001] getaddrinfo failed'))
2019-07-10 14:09:58 logger.py[line:90] ERROR HTTPConnectionPool(host='chrome-scan', port=4444): Max retries exceeded with url: /wd/hub/session (Caused by NewConnectionError('<urllib3.connection.HTTPConnection object at 0x00000162EE91A668>: Failed to establish a new connection: [Errno 11001] getaddrinfo failed'))
2019-07-10 14:10:00 logger.py[line:90] ERROR HTTPConnectionPool(host='chrome-scan', port=4444): Max retries exceeded with url: /wd/hub/session (Caused by NewConnectionError('<urllib3.connection.HTTPConnection object at 0x00000162EE91A780>: Failed to establish a new connection: [Errno 11001] getaddrinfo failed'))
2019-07-10 14:10:02 logger.py[line:90] ERROR HTTPConnectionPool(host='chrome-scan', port=4444): Max retries exceeded with url: /wd/hub/session (Caused by NewConnectionError('<urllib3.connection.HTTPConnection object at 0x00000162EE91A898>: Failed to establish a new connection: [Errno 11001] getaddrinfo failed'))
2019-07-10 14:10:05 logger.py[line:90] ERROR HTTPConnectionPool(host='chrome-scan', port=4444): Max retries exceeded with url: /wd/hub/session (Caused by NewConnectionError('<urllib3.connection.HTTPConnection object at 0x00000162EE91A9B0>: Failed to establish a new connection: [Errno 11001] getaddrinfo failed'))
2019-07-10 14:10:07 logger.py[line:90] ERROR HTTPConnectionPool(host='chrome-scan', port=4444): Max retries exceeded with url: /wd/hub/session (Caused by NewConnectionError('<urllib3.connection.HTTPConnection object at 0x00000162EE91AAC8>: Failed to establish a new connection: [Errno 11001] getaddrinfo failed'))
2019-07-10 14:10:09 logger.py[line:90] ERROR HTTPConnectionPool(host='chrome-scan', port=4444): Max retries exceeded with url: /wd/hub/session (Caused by NewConnectionError('<urllib3.connection.HTTPConnection object at 0x00000162EE91ABE0>: Failed to establish a new connection: [Errno 11001] getaddrinfo failed'))
2019-07-10 14:10:11 logger.py[line:90] ERROR HTTPConnectionPool(host='chrome-scan', port=4444): Max retries exceeded with url: /wd/hub/session (Caused by NewConnectionError('<urllib3.connection.HTTPConnection object at 0x00000162EE91ACF8>: Failed to establish a new connection: [Errno 11001] getaddrinfo failed'))
2019-07-10 14:10:16 logger.py[line:90] ERROR 请检查好Chrome环境！
2019-07-10 14:10:16 logger.py[line:90] ERROR 请检查好Chrome环境！
2019-07-10 14:10:17 logger.py[line:90] ERROR 请检查好Chrome环境！
2019-07-10 14:10:17 logger.py[line:90] ERROR 请检查好Chrome环境！
2019-07-10 14:10:17 logger.py[line:90] ERROR 请检查好Chrome环境！
2019-07-10 14:10:17 logger.py[line:90] ERROR 请检查好Chrome环境！
2019-07-10 14:10:17 logger.py[line:90] ERROR 请检查好Chrome环境！
2019-07-10 14:10:17 logger.py[line:90] ERROR 请检查好Chrome环境！
2019-07-10 14:10:40 logger.py[line:90] ERROR list index out of range
2019-07-10 14:10:42 logger.py[line:90] ERROR list index out of range
2019-07-10 14:11:18 logger.py[line:96] DEBUG =================扫描程序开始==========================
2019-07-10 14:12:02 logger.py[line:90] ERROR HTTPConnectionPool(host='chrome-scan', port=4444): Max retries exceeded with url: /wd/hub/session (Caused by NewConnectionError('<urllib3.connection.HTTPConnection object at 0x00000241E3881A20>: Failed to establish a new connection: [Errno 11001] getaddrinfo failed'))
2019-07-10 14:12:29 logger.py[line:90] ERROR HTTPConnectionPool(host='chrome-scan', port=4444): Max retries exceeded with url: /wd/hub/session (Caused by NewConnectionError('<urllib3.connection.HTTPConnection object at 0x00000241E37AEEB8>: Failed to establish a new connection: [Errno 11001] getaddrinfo failed'))
2019-07-10 14:12:36 logger.py[line:90] ERROR HTTPConnectionPool(host='chrome-scan', port=4444): Max retries exceeded with url: /wd/hub/session (Caused by NewConnectionError('<urllib3.connection.HTTPConnection object at 0x00000241E3841FD0>: Failed to establish a new connection: [Errno 11001] getaddrinfo failed'))
2019-07-10 14:12:38 logger.py[line:90] ERROR HTTPConnectionPool(host='chrome-scan', port=4444): Max retries exceeded with url: /wd/hub/session (Caused by NewConnectionError('<urllib3.connection.HTTPConnection object at 0x00000241E3841CF8>: Failed to establish a new connection: [Errno 11001] getaddrinfo failed'))
2019-07-10 14:12:58 logger.py[line:90] ERROR HTTPConnectionPool(host='chrome-scan', port=4444): Max retries exceeded with url: /wd/hub/session (Caused by NewConnectionError('<urllib3.connection.HTTPConnection object at 0x00000241E3A7C470>: Failed to establish a new connection: [Errno 11001] getaddrinfo failed'))
2019-07-10 14:13:01 logger.py[line:90] ERROR HTTPConnectionPool(host='chrome-scan', port=4444): Max retries exceeded with url: /wd/hub/session (Caused by NewConnectionError('<urllib3.connection.HTTPConnection object at 0x00000241E3A7C390>: Failed to establish a new connection: [Errno 11001] getaddrinfo failed'))
2019-07-10 14:13:03 logger.py[line:90] ERROR HTTPConnectionPool(host='chrome-scan', port=4444): Max retries exceeded with url: /wd/hub/session (Caused by NewConnectionError('<urllib3.connection.HTTPConnection object at 0x00000241E3A7C278>: Failed to establish a new connection: [Errno 11001] getaddrinfo failed'))
2019-07-10 14:13:05 logger.py[line:90] ERROR HTTPConnectionPool(host='chrome-scan', port=4444): Max retries exceeded with url: /wd/hub/session (Caused by NewConnectionError('<urllib3.connection.HTTPConnection object at 0x00000241E3A7C6D8>: Failed to establish a new connection: [Errno 11001] getaddrinfo failed'))
2019-07-10 14:13:07 logger.py[line:90] ERROR 请检查好Chrome环境！
2019-07-10 14:18:53 logger.py[line:96] DEBUG =================扫描程序开始==========================
2019-07-10 14:20:09 logger.py[line:90] ERROR HTTPConnectionPool(host='chrome-scan', port=4444): Max retries exceeded with url: /wd/hub/session (Caused by NewConnectionError('<urllib3.connection.HTTPConnection object at 0x00000282D3A96F28>: Failed to establish a new connection: [Errno 11001] getaddrinfo failed'))
2019-07-10 14:20:11 logger.py[line:90] ERROR HTTPConnectionPool(host='chrome-scan', port=4444): Max retries exceeded with url: /wd/hub/session (Caused by NewConnectionError('<urllib3.connection.HTTPConnection object at 0x00000282D3ABB0B8>: Failed to establish a new connection: [Errno 11001] getaddrinfo failed'))
2019-07-10 14:20:13 logger.py[line:90] ERROR HTTPConnectionPool(host='chrome-scan', port=4444): Max retries exceeded with url: /wd/hub/session (Caused by NewConnectionError('<urllib3.connection.HTTPConnection object at 0x00000282D3ABB208>: Failed to establish a new connection: [Errno 11001] getaddrinfo failed'))
2019-07-10 14:20:15 logger.py[line:90] ERROR HTTPConnectionPool(host='chrome-scan', port=4444): Max retries exceeded with url: /wd/hub/session (Caused by NewConnectionError('<urllib3.connection.HTTPConnection object at 0x00000282D3ABB358>: Failed to establish a new connection: [Errno 11001] getaddrinfo failed'))
2019-07-10 14:20:18 logger.py[line:90] ERROR HTTPConnectionPool(host='chrome-scan', port=4444): Max retries exceeded with url: /wd/hub/session (Caused by NewConnectionError('<urllib3.connection.HTTPConnection object at 0x00000282D3ABB4A8>: Failed to establish a new connection: [Errno 11001] getaddrinfo failed'))
2019-07-10 14:20:20 logger.py[line:90] ERROR HTTPConnectionPool(host='chrome-scan', port=4444): Max retries exceeded with url: /wd/hub/session (Caused by NewConnectionError('<urllib3.connection.HTTPConnection object at 0x00000282D3ABB5F8>: Failed to establish a new connection: [Errno 11001] getaddrinfo failed'))
2019-07-10 14:20:22 logger.py[line:90] ERROR HTTPConnectionPool(host='chrome-scan', port=4444): Max retries exceeded with url: /wd/hub/session (Caused by NewConnectionError('<urllib3.connection.HTTPConnection object at 0x00000282D3ABB748>: Failed to establish a new connection: [Errno 11001] getaddrinfo failed'))
2019-07-10 14:20:24 logger.py[line:90] ERROR HTTPConnectionPool(host='chrome-scan', port=4444): Max retries exceeded with url: /wd/hub/session (Caused by NewConnectionError('<urllib3.connection.HTTPConnection object at 0x00000282D3ABB898>: Failed to establish a new connection: [Errno 11001] getaddrinfo failed'))
2019-07-10 14:20:30 logger.py[line:90] ERROR 请检查好Chrome环境！
2019-07-10 14:20:30 logger.py[line:90] ERROR 请检查好Chrome环境！
2019-07-10 14:20:30 logger.py[line:90] ERROR 请检查好Chrome环境！
2019-07-10 14:20:30 logger.py[line:90] ERROR 请检查好Chrome环境！
2019-07-10 14:20:30 logger.py[line:90] ERROR 请检查好Chrome环境！
2019-07-10 14:20:30 logger.py[line:90] ERROR 请检查好Chrome环境！
2019-07-10 14:20:30 logger.py[line:90] ERROR 请检查好Chrome环境！
2019-07-10 14:20:30 logger.py[line:90] ERROR 请检查好Chrome环境！
2019-07-10 14:20:51 logger.py[line:90] ERROR Message: unknown error: Element <a data-click="{
			'F':'778317EA',
			'F1':'9D73F1E4',
			'F2':'4CA6DC6B',
			'F3':'54E52437',
			'T':'1562739632',
						'y':'4BB3DE67'
			 
									}" href="http://www.baidu.com/link?url=v6TlO3NRPpOmxsFpwD3VT4Qtd2dMKGF_En-tDQlO2JtoFUalNVV7y5Z0GE6Vr3c4" target="_blank">...</a> is not clickable at point (149, 8). Other element would receive the click: <div class="s_form">...</div>
  (Session info: chrome=75.0.3770.100)
  (Driver info: chromedriver=2.37.544315 (730aa6a5fdba159ac9f4c1e8cbc59bf1b5ce12b7),platform=Windows NT 10.0.14393 x86_64)

2019-07-10 14:20:52 logger.py[line:90] ERROR Message: unknown error: Element <a href="/s?wd=%E5%A9%B4%E6%AF%8D%E7%9F%A5%E8%B5%84%E8%AE%AF&amp;pn=10&amp;oq=%E5%A9%B4%E6%AF%8D%E7%9F%A5%E8%B5%84%E8%AE%AF&amp;ie=utf-8&amp;rsv_idx=1&amp;rsv_pq=c1a99224000c4527&amp;rsv_t=9468b6N7Pr6qWetJIE3SyB29RYXPSUtEIHYawlYwDPA371pIkeOdhDxTyz0&amp;rsv_page=1" class="n">...</a> is not clickable at point (615, 864). Other element would receive the click: <div id="foot">...</div>
  (Session info: chrome=75.0.3770.100)
  (Driver info: chromedriver=2.37.544315 (730aa6a5fdba159ac9f4c1e8cbc59bf1b5ce12b7),platform=Windows NT 10.0.14393 x86_64)

2019-07-10 14:23:27 logger.py[line:96] DEBUG =================扫描程序开始==========================
2019-07-10 14:24:42 logger.py[line:90] ERROR HTTPConnectionPool(host='chrome-scan', port=4444): Max retries exceeded with url: /wd/hub/session (Caused by NewConnectionError('<urllib3.connection.HTTPConnection object at 0x00000238798A1470>: Failed to establish a new connection: [Errno 11001] getaddrinfo failed'))
2019-07-10 14:24:44 logger.py[line:90] ERROR HTTPConnectionPool(host='chrome-scan', port=4444): Max retries exceeded with url: /wd/hub/session (Caused by NewConnectionError('<urllib3.connection.HTTPConnection object at 0x00000238798A1588>: Failed to establish a new connection: [Errno 11001] getaddrinfo failed'))
2019-07-10 14:24:46 logger.py[line:90] ERROR HTTPConnectionPool(host='chrome-scan', port=4444): Max retries exceeded with url: /wd/hub/session (Caused by NewConnectionError('<urllib3.connection.HTTPConnection object at 0x00000238798A16A0>: Failed to establish a new connection: [Errno 11001] getaddrinfo failed'))
2019-07-10 14:24:48 logger.py[line:90] ERROR HTTPConnectionPool(host='chrome-scan', port=4444): Max retries exceeded with url: /wd/hub/session (Caused by NewConnectionError('<urllib3.connection.HTTPConnection object at 0x00000238798A17B8>: Failed to establish a new connection: [Errno 11001] getaddrinfo failed'))
2019-07-10 14:24:51 logger.py[line:90] ERROR HTTPConnectionPool(host='chrome-scan', port=4444): Max retries exceeded with url: /wd/hub/session (Caused by NewConnectionError('<urllib3.connection.HTTPConnection object at 0x00000238798A18D0>: Failed to establish a new connection: [Errno 11001] getaddrinfo failed'))
2019-07-10 14:24:53 logger.py[line:90] ERROR HTTPConnectionPool(host='chrome-scan', port=4444): Max retries exceeded with url: /wd/hub/session (Caused by NewConnectionError('<urllib3.connection.HTTPConnection object at 0x00000238798A19E8>: Failed to establish a new connection: [Errno 11001] getaddrinfo failed'))
2019-07-10 14:24:55 logger.py[line:90] ERROR HTTPConnectionPool(host='chrome-scan', port=4444): Max retries exceeded with url: /wd/hub/session (Caused by NewConnectionError('<urllib3.connection.HTTPConnection object at 0x00000238798A1B00>: Failed to establish a new connection: [Errno 11001] getaddrinfo failed'))
2019-07-10 14:24:57 logger.py[line:90] ERROR HTTPConnectionPool(host='chrome-scan', port=4444): Max retries exceeded with url: /wd/hub/session (Caused by NewConnectionError('<urllib3.connection.HTTPConnection object at 0x00000238798A1C18>: Failed to establish a new connection: [Errno 11001] getaddrinfo failed'))
2019-07-10 14:25:03 logger.py[line:90] ERROR 请检查好Chrome环境！
2019-07-10 14:25:03 logger.py[line:90] ERROR 请检查好Chrome环境！
2019-07-10 14:25:03 logger.py[line:90] ERROR 请检查好Chrome环境！
2019-07-10 14:25:03 logger.py[line:90] ERROR 请检查好Chrome环境！
2019-07-10 14:25:03 logger.py[line:90] ERROR 请检查好Chrome环境！
2019-07-10 14:25:03 logger.py[line:90] ERROR 请检查好Chrome环境！
2019-07-10 14:25:03 logger.py[line:90] ERROR 请检查好Chrome环境！
2019-07-10 14:25:03 logger.py[line:90] ERROR 请检查好Chrome环境！
2019-07-10 14:27:26 logger.py[line:96] DEBUG =================扫描程序结束==========================
2019-07-10 14:28:05 logger.py[line:96] DEBUG =================扫描程序开始==========================
2019-07-10 14:29:20 logger.py[line:90] ERROR HTTPConnectionPool(host='chrome-scan', port=4444): Max retries exceeded with url: /wd/hub/session (Caused by NewConnectionError('<urllib3.connection.HTTPConnection object at 0x000001A3701B43C8>: Failed to establish a new connection: [Errno 11001] getaddrinfo failed'))
2019-07-10 14:29:22 logger.py[line:90] ERROR HTTPConnectionPool(host='chrome-scan', port=4444): Max retries exceeded with url: /wd/hub/session (Caused by NewConnectionError('<urllib3.connection.HTTPConnection object at 0x000001A3701B44E0>: Failed to establish a new connection: [Errno 11001] getaddrinfo failed'))
2019-07-10 14:29:24 logger.py[line:90] ERROR HTTPConnectionPool(host='chrome-scan', port=4444): Max retries exceeded with url: /wd/hub/session (Caused by NewConnectionError('<urllib3.connection.HTTPConnection object at 0x000001A3701B45F8>: Failed to establish a new connection: [Errno 11001] getaddrinfo failed'))
2019-07-10 14:29:27 logger.py[line:90] ERROR HTTPConnectionPool(host='chrome-scan', port=4444): Max retries exceeded with url: /wd/hub/session (Caused by NewConnectionError('<urllib3.connection.HTTPConnection object at 0x000001A3701B4710>: Failed to establish a new connection: [Errno 11001] getaddrinfo failed'))
2019-07-10 14:29:29 logger.py[line:90] ERROR HTTPConnectionPool(host='chrome-scan', port=4444): Max retries exceeded with url: /wd/hub/session (Caused by NewConnectionError('<urllib3.connection.HTTPConnection object at 0x000001A3701B4828>: Failed to establish a new connection: [Errno 11001] getaddrinfo failed'))
2019-07-10 14:29:31 logger.py[line:90] ERROR HTTPConnectionPool(host='chrome-scan', port=4444): Max retries exceeded with url: /wd/hub/session (Caused by NewConnectionError('<urllib3.connection.HTTPConnection object at 0x000001A3701B4940>: Failed to establish a new connection: [Errno 11001] getaddrinfo failed'))
2019-07-10 14:29:33 logger.py[line:90] ERROR HTTPConnectionPool(host='chrome-scan', port=4444): Max retries exceeded with url: /wd/hub/session (Caused by NewConnectionError('<urllib3.connection.HTTPConnection object at 0x000001A3701B4A58>: Failed to establish a new connection: [Errno 11001] getaddrinfo failed'))
2019-07-10 14:29:36 logger.py[line:90] ERROR HTTPConnectionPool(host='chrome-scan', port=4444): Max retries exceeded with url: /wd/hub/session (Caused by NewConnectionError('<urllib3.connection.HTTPConnection object at 0x000001A3701B4B70>: Failed to establish a new connection: [Errno 11001] getaddrinfo failed'))
2019-07-10 14:29:41 logger.py[line:90] ERROR 请检查好Chrome环境！
2019-07-10 14:29:41 logger.py[line:90] ERROR 请检查好Chrome环境！
2019-07-10 14:29:41 logger.py[line:90] ERROR 请检查好Chrome环境！
2019-07-10 14:29:41 logger.py[line:90] ERROR 请检查好Chrome环境！
2019-07-10 14:29:41 logger.py[line:90] ERROR 请检查好Chrome环境！
2019-07-10 14:29:41 logger.py[line:90] ERROR 请检查好Chrome环境！
2019-07-10 14:29:41 logger.py[line:90] ERROR 请检查好Chrome环境！
2019-07-10 14:29:42 logger.py[line:90] ERROR 请检查好Chrome环境！
2019-07-10 14:32:01 logger.py[line:96] DEBUG =================扫描程序结束==========================
