2019-07-06 16:02:16 logger.py[line:96] DEBUG =================扫描程序结束==========================
2019-07-06 16:04:54 logger.py[line:96] DEBUG =================扫描程序开始==========================
2019-07-06 16:05:32 logger.py[line:90] ERROR HTTPConnectionPool(host='chrome-scan', port=4444): Max retries exceeded with url: /wd/hub/session (Caused by NewConnectionError('<urllib3.connection.HTTPConnection object at 0x0000026F4D3DCAC8>: Failed to establish a new connection: [Errno 11001] getaddrinfo failed'))
2019-07-06 16:05:35 logger.py[line:90] ERROR HTTPConnectionPool(host='chrome-scan', port=4444): Max retries exceeded with url: /wd/hub/session (Caused by NewConnectionError('<urllib3.connection.HTTPConnection object at 0x0000026F4D3DCBE0>: Failed to establish a new connection: [Errno 11001] getaddrinfo failed'))
2019-07-06 16:05:37 logger.py[line:90] ERROR HTTPConnectionPool(host='chrome-scan', port=4444): Max retries exceeded with url: /wd/hub/session (Caused by NewConnectionError('<urllib3.connection.HTTPConnection object at 0x0000026F4D3DCCF8>: Failed to establish a new connection: [Errno 11001] getaddrinfo failed'))
2019-07-06 16:05:39 logger.py[line:90] ERROR HTTPConnectionPool(host='chrome-scan', port=4444): Max retries exceeded with url: /wd/hub/session (Caused by NewConnectionError('<urllib3.connection.HTTPConnection object at 0x0000026F4D3DCE48>: Failed to establish a new connection: [Errno 11001] getaddrinfo failed'))
2019-07-06 16:05:44 logger.py[line:90] ERROR 请检查好Chrome环境！
2019-07-06 16:05:44 logger.py[line:90] ERROR 请检查好Chrome环境！
2019-07-06 16:05:44 logger.py[line:90] ERROR 请检查好Chrome环境！
2019-07-06 16:05:44 logger.py[line:90] ERROR 请检查好Chrome环境！
2019-07-06 16:08:21 logger.py[line:96] DEBUG =================扫描程序结束==========================
